Workbook

Sheet JO#1
A1: Municipal P A Y R O L L
A2: WE HEREBY ACKNOWLEDGE TO HAVE RECEIVED FROM MINERVA L. BOONGALING, TREASURER OF PAGSANJAN, LAGUNA THE SUMS HEREIN SPECIFIED OPPOSITES OUR RESPECTIVE NAMES, THE SAME BEING FULL COMPENSATION FOR OUR SERVICES RENDERED DURING THE PERIOD STATED BELOW, TO THE CORRECTNESS OF WHICH WE HEREBY SEVERALLY
A4: NO. | B4: NAME | C4: DESIGNATION | D4: PERIOD OF SERVICE (INCLUSIVE DATES) | H4: AMOUNT ACCRUED FOR THE PERIOD | I4: D E D U C T I O N S
D5: FROM | E5: TO | I5: Hazard Pay | J5: SOS | K5: ESL | N5: GOVERNMENT SERVICE INSURANCE SYSTEM | AC5: AMOUNT PAID IN CASH (CR.A-1) | AD5: NO.
M6: EL | O6: POLICY LOAN | P6: MEDICARE | R6: LIFE/RETIREMENT | X6: GLOBE | Y6: RBP | AE6: SIGNATURE OF PAYEE | AF6: REMARKS
P7: PERSONAL SHARE | Q7: GOV'T. SHARE | R7: INSURANCE PREMIUM | V7: CAL | W7: UOLI | AB7: STATE. INSURANCE
F8: Daily Rate | G8: No. of | R8: PERSONAL SHARE | S8: GOV'T. SHARE | T8: OPTIONAL | U8: UOLI
G9: Days | Q9: Hazard
A10: 1 | B10: 2 | C10: 3 | D10: 4 | E10: 5 | F10: 6 | H10: 7 | I10: 8 | J10: 9 | K10: 10 | L10: 11 | M10: 12 | N10: 13 | O10: 12 | P10: 13 | Q10: 14 | R10: 15 | S10: 16 | T10: 17 | U10: 18 | V10: 21 | W10: 22 | X10: 23 | Y10: 24 | Z10: 19 | AA10: 20 | AB10: 21 | AC10: 22 | AD10: 23 | AE10: 24 | AF10: 25
A11: 1 | B11: 1031 | D11: Mar. 1-15, 2017 | AD11: 1
A12: 2 | B12: BON-TAG ANI-QUISMUNDO | C12: Admin Aide I | D12: - d | E12: o- | F12: 344.63 | G12: 11 | H12: =F12*G12 -> 3790.93 | AC12: =SUM(H12:AB12) -> 3790.93 | AD12: 2
A13: 3 | B13: 1041 | AD13: 3
A14: 4 | B14: MARIZ TORRES | C14: Admin Aide I | D14: - d | E14: o- | F14: 344.63 | G14: 11 | H14: =F14*G14 -> 3790.93 | AC14: =SUM(H14:AB14) -> 3790.93 | AD14: 4
A15: 5 | B15: JERICO CALCETAS | C15: Admin Aide I | D15: - d | E15: o- | F15: 344.63 | G15: 13 | H15: =F15*G15 -> 4480.19 | AC15: =SUM(H15:AB15) -> 4480.19 | AD15: 5
A16: 6 | B16: CANDY LOU DEL ROSARIO | C16: Admin Aide I | D16: - d | E16: o- | F16: 344.63 | G16: 13 | H16: =F16*G16 -> 4480.19 | AC16: =SUM(H16:AB16) -> 4480.19 | AD16: 6
A17: 7 | AD17: 7
A18: 8 | B18: 1061 | AD18: 8
A19: 9 | B19: JAIME PANGUITO | C19: Admin Aide I | D19: - d | E19: o- | F19: 344.63 | G19: 12 | H19: =F19*G19 -> 4135.56 | AC19: =SUM(H19:AB19) -> 4135.56 | AD19: 9
A20: 10 | B20: JOANNA ELIAZAR | C20: Admin Aide I | D20: - d | E20: o- | F20: 344.63 | G20: 12 | H20: =F20*G20 -> 4135.56 | AC20: =SUM(H20:AB20) -> 4135.56 | AD20: 10
A21: 11 | B21: 1081 | AD21: 11
A22: 12 | B22: HERLYN CABALLES | C22: Admin Aide I | D22: - d | E22: o- | F22: 344.63 | G22: 11 | H22: =F22*G22 -> 3790.93 | AC22: =SUM(H22:AB22) -> 3790.93 | AD22: 12
A23: 13 | B23: 7611 | AD23: 13
A24: 14 | B24: JOHN CHRISTIAM ABARQUEZ | C24: Admin Aide I | D24: - d | E24: o- | F24: 344.63 | G24: 11 | H24: =F24*G24 -> 3790.93 | AC24: =SUM(H24:AB24) -> 3790.93 | AD24: 14
A25: 15 | B25: DORIE LERON | C25: Admin Aide I | D25: - d | E25: o- | F25: 344.63 | G25: 11 | H25: =F25*G25 -> 3790.93 | AC25: =SUM(H25:AB25) -> 3790.93 | AD25: 15
A26: 16 | B26: ROGELIO CONTEGINO | C26: Admin Aide I | D26: - d | E26: o- | F26: 344.63 | G26: 11 | H26: =F26*G26 -> 3790.93 | AC26: =SUM(H26:AB26) -> 3790.93 | AD26: 16
A27: 17 | B27: 8711 | AD27: 17
A28: 18 | B28: TENNESEE WYLIE BALETE | C28: Admin Aide I | D28: - d | E28: o- | F28: 344.63 | G28: 15 | H28: =F28*G28 -> 5169.45 | AC28: =SUM(H28:AB28) -> 5169.45 | AD28: 18
A29: 19 | B29: 8731 | AD29: 19
A30: 20 | B30: ALFREDO GONZALES | C30: Admin Aide I | D30: - d | E30: o- | F30: 344.63 | G30: 14 | H30: =F30*G30 -> 4824.82 | AC30: =SUM(H30:AB30) -> 4824.82 | AD30: 20
A31: 21 | B31: RODANTE LORENZANA | C31: Admin Aide I | D31: - d | E31: o- | F31: 344.63 | G31: 13 | H31: =F31*G31 -> 4480.19 | AC31: =SUM(H31:AB31) -> 4480.19 | AD31: 21
A32: 22 | B32: ROBERTO BRECINIO | C32: Admin Aide I | D32: - d | E32: o- | F32: 344.63 | G32: 15 | H32: =F32*G32 -> 5169.45 | AC32: =SUM(H32:AB32) -> 5169.45 | AD32: 22
A33: 23 | B33: 8811 | AD33: 23
A34: 24 | B34: ALDRIN BUENA | C34: Admin Aide I | D34: - d | E34: o- | F34: 344.63 | G34: 13 | H34: =F34*G34 -> 4480.19 | AC34: =SUM(H34:AB34) -> 4480.19 | AD34: 24
A35: 25 | B35: JONATHAN AZULA | C35: Admin Aide I | D35: - d | E35: o- | F35: 344.63 | G35: 13 | H35: =F35*G35 -> 4480.19 | AC35: =SUM(H35:AB35) -> 4480.19 | AD35: 25
A36: 26 | B36: 8852 | AD36: 26
A37: 27 | B37: ROMANO ALMERA | C37: Admin Aide I | D37: - d | E37: o- | F37: 344.63 | G37: 12 | H37: =F37*G37 -> 4135.56 | AC37: =SUM(H37:AB37) -> 4135.56 | AD37: 27
A38: 28 | B38: NESTOR GABALENO | C38: Admin Aide I | D38: - d | E38: o- | F38: 344.63 | G38: 13 | H38: =F38*G38 -> 4480.19 | AC38: =SUM(H38:AB38) -> 4480.19 | AD38: 28
A39: 29 | B39: ERIK JAVIER | C39: Admin Aide I | D39: - d | E39: o- | F39: 344.63 | G39: 13 | H39: =F39*G39 -> 4480.19 | AC39: =SUM(H39:AB39) -> 4480.19 | AD39: 29
A40: 30 | B40: LED VENI PENIDO | C40: Admin Aide I | D40: - d | E40: o- | F40: 344.63 | G40: 13 | H40: =F40*G40 -> 4480.19 | AC40: =SUM(H40:AB40) -> 4480.19 | AD40: 30
A41: 31 | H41: =SUM(H12:H40) -> 86157.5 | AC41: =SUM(AC12:AC40)+I41 -> 86157.5 | AD41: 31
...

Sheet JOmto
A1: Municipal P A Y R O L L
A2: WE HEREBY ACKNOWLEDGE TO HAVE RECEIVED FROM MINERVA L. BOONGALING, TREASURER OF PAGSANJAN, LAGUNA THE SUMS HEREIN SPECIFIED OPPOSITES OUR RESPECTIVE NAMES, THE SAME BEING FULL COMPENSATION FOR OUR SERVICES RENDERED DURING THE PERIOD STATED BELOW, TO THE CORRECTNESS OF WHICH WE HEREBY SEVERALLY
A4: NO. | B4: NAME | C4: DESIGNATION | D4: PERIOD OF SERVICE (INCLUSIVE DATES) | H4: AMOUNT ACCRUED FOR THE PERIOD | I4: D E D U C T I O N S
D5: FROM | E5: TO | I5: Hazard Pay | J5: SOS | K5: ESL | N5: GOVERNMENT SERVICE INSURANCE SYSTEM | AC5: AMOUNT PAID IN CASH (CR.A-1) | AD5: NO.
M6: EL | O6: POLICY LOAN | P6: MEDICARE | R6: LIFE/RETIREMENT | X6: GLOBE | Y6: RBP | AE6: SIGNATURE OF PAYEE | AF6: REMARKS
P7: PERSONAL SHARE | Q7: GOV'T. SHARE | R7: INSURANCE PREMIUM | V7: CAL | W7: UOLI | AB7: STATE. INSURANCE
F8: Daily Rate | G8: No. of | R8: PERSONAL SHARE | S8: GOV'T. SHARE | T8: OPTIONAL | U8: UOLI
G9: Days | Q9: Hazard
A10: 1 | B10: 2 | C10: 3 | D10: 4 | E10: 5 | F10: 6 | H10: 7 | I10: 8 | J10: 9 | K10: 10 | L10: 11 | M10: 12 | N10: 13 | O10: 12 | P10: 13 | Q10: 14 | R10: 15 | S10: 16 | T10: 17 | U10: 18 | V10: 21 | W10: 22 | X10: 23 | Y10: 24 | Z10: 19 | AA10: 20 | AB10: 21 | AC10: 22 | AD10: 23 | AE10: 24 | AF10: 25
A11: 26 | B11: 8852 | AD11: 26
A12: 27 | B12: ROMANO ALMERA | C12: Admin Aide I | D12: Mar. 16-31, 2017 | F12: 344.63 | G12: 13 | H12: =F12*G12 -> 4480.19 | AC12: =SUM(H12:AB12) -> 4480.19 | AD12: 27
A13: 28 | B13: NESTOR GABALENO | C13: Admin Aide I | D13: - d | E13: o- | F13: 344.63 | G13: 14 | H13: =F13*G13 -> 4824.82 | AC13: =SUM(H13:AB13) -> 4824.82 | AD13: 28
A14: 29 | B14: ERIK JAVIER | C14: Admin Aide I | D14: - d | E14: o- | F14: 344.63 | G14: 14 | H14: =F14*G14 -> 4824.82 | AC14: =SUM(H14:AB14) -> 4824.82 | AD14: 29
A15: 30 | B15: LED VENI PENIDO | C15: Admin Aide I | D15: - d | E15: o- | F15: 344.63 | G15: 14 | H15: =F15*G15 -> 4824.82 | AC15: =SUM(H15:AB15) -> 4824.82 | AD15: 30
A27: 31 | H27: =SUM(H11:H26) -> 18954.65 | AC27: =SUM(AC11:AC26)+I27 -> 18954.65 | AD27: 31
A28: (1) I HEREBY CERTIFY on my official oath that the above PAYROLL is correct, and that services above stated have been duly rendered. Payment for such services is also hereby approved from the appropriation indicated. | I28: (4) APPROVED | AB28: (5) I HEREBY CERTIFY on my official oath that I have paid in cash to each official and employee whose name appears on the above roll the amount set opposite his name, under column 22, he having signed or marked his name under column 24 above, in my presence and at the time that payment was made to him, in acknowledgement of receipt of the money paid him.
J30: GIRLIE JAVIER EJERCITO
J31: Municipal Mayor
C32: ARCH. MANSLEY G. KIMHOKO | J32: Chief of Office
D33: Municipal Tourism Officer
A35: (2) APPROVED for payment subject to preaudit:
E37: Treasurer | AB37: (6) I HEREBY CERTIFY on my official oath that each employee whose name appears on the above roll has been paid in cash or in check, and in no other mode, the amount shown under column 22 above, opposite his name. The total of the payments made by means this payroll amount to
A39: (3) Preaudited and approved for payment in the month of
C41: (P ) | E41: pesos only.
C42: Provincial Auditor | AF42: Treasurer

Sheet JO#02
A1: Municipal P A Y R O L L
A2: WE HEREBY ACKNOWLEDGE TO HAVE RECEIVED FROM MINERVA L. BOONGALING, TREASURER OF PAGSANJAN, LAGUNA THE SUMS HEREIN SPECIFIED OPPOSITES OUR RESPECTIVE NAMES, THE SAME BEING FULL COMPENSATION FOR OUR SERVICES RENDERED DURING THE PERIOD STATED BELOW, TO THE CORRECTNESS OF WHICH WE HEREBY SEVERALLY
A4: NO. | B4: NAME | C4: DESIGNATION | D4: PERIOD OF SERVICE (INCLUSIVE DATES) | H4: AMOUNT ACCRUED FOR THE PERIOD | I4: D E D U C T I O N S
D5: FROM | E5: TO | I5: Hazard Pay | J5: SOS | K5: ESL | N5: GOVERNMENT SERVICE INSURANCE SYSTEM | AC5: AMOUNT PAID IN CASH (CR.A-1) | AD5: N U M B E R
G6: Mothly Rate | M6: EL | O6: POLICY LOAN | P6: MEDICARE | R6: LIFE/RETIREMENT | X6: GLOBE | Y6: RBP | AE6: SIGNATURE OF PAYEE | AF6: REMARKS
P7: PERSONAL SHARE | Q7: GOV'T. SHARE | R7: INSURANCE PREMIUM | V7: CAL | W7: UOLI | AB7: STATE. INSURANCE
G8: Daily Rate | R8: PERSONAL SHARE | S8: GOV'T. SHARE | T8: OPTIONAL | U8: UOLI
Q9: Hazard
A10: 1 | B10: 2 | C10: 3 | D10: 4 | E10: 5 | G10: 6 | H10: 7 | I10: 8 | J10: 9 | K10: 10 | L10: 11 | M10: 12 | N10: 13 | O10: 12 | P10: 13 | Q10: 14 | R10: 15 | S10: 16 | T10: 17 | U10: 18 | V10: 21 | W10: 22 | X10: 23 | Y10: 24 | Z10: 19 | AA10: 20 | AB10: 21 | AC10: 22 | AD10: 23 | AE10: 24 | AF10: 25
A11: 1 | B11: 1031 | AD11: 1
A12: 2 | B12: BON-TAG ANI-QUISMUNDO | C12: Admin Aide I | D12: Mar. 16-31 | F12: 12 | G12: 344.63 | H12: =G12*F12 -> 4135.56 | AC12: =SUM(H12:AB12) -> 4135.56 | AD12: 2
A13: 3 | B13: 1041 | AD13: 3
A14: 4 | B14: MARIZ TORRES | C14: Admin Aide I | D14: - d | E14: o- | F14: 11 | G14: 344.63 | H14: =G14*F14 -> 3790.93 | AC14: =SUM(H14:AB14) -> 3790.93 | AD14: 4
A15: 5 | B15: JERICO CALCETAS | C15: Admin Aide I | D15: - d | E15: o- | F15: 14 | G15: 344.63 | H15: =G15*F15 -> 4824.82 | AC15: =SUM(H15:AB15) -> 4824.82 | AD15: 5
A16: 6 | B16: CANDY LOU DEL ROSARIO | C16: Admin Aide I | D16: - d | E16: o- | F16: 17.5 | G16: 344.63 | H16: =G16*F16 -> 6031.025 | AC16: =SUM(H16:AB16) -> 6031.025 | AD16: 6
A17: 7 | B17: 1061 | AD17: 7
A18: 8 | B18: JAIME PANGUITO | C18: Admin Aide I | D18: - d | E18: o- | F18: 12 | G18: 344.63 | H18: =G18*F18 -> 4135.56 | AC18: =SUM(H18:AB18) -> 4135.56 | AD18: 8
A19: 9 | B19: JOANNA ELIAZAR | C19: Admin Aide I | D19: - d | E19: o- | F19: 11 | G19: 344.63 | H19: =G19*F19 -> 3790.93 | AC19: =SUM(H19:AB19) -> 3790.93 | AD19: 9
A20: 10 | B20: 1081 | AD20: 10
A21: 11 | B21: HERLYN CABALLES | C21: Admin Aide I | D21: - d | E21: o- | F21: 12 | G21: 344.63 | H21: =G21*F21 -> 4135.56 | AC21: =SUM(H21:AB21) -> 4135.56 | AD21: 11
A22: 20 | B22: 7611 | AD22: 20
A23: 21 | B23: JOHN CHRISTIAM ABARQUEZ | C23: Admin Aide I | D23: - d | E23: o- | F23: 11 | G23: 344.63 | H23: =G23*F23 -> 3790.93 | AC23: =SUM(H23:AB23) -> 3790.93 | AD23: 21
A24: 22 | B24: DORIE LERON | C24: Admin Aide I | D24: - d | E24: o- | F24: 12 | G24: 344.63 | H24: =G24*F24 -> 4135.56 | AC24: =SUM(H24:AB24) -> 4135.56 | AD24: 22
A25: 23 | B25: ROGELIO CONTEGINO | C25: Admin Aide I | D25: - d | E25: o- | F25: 12 | G25: 344.63 | H25: =G25*F25 -> 4135.56 | AC25: =SUM(H25:AB25) -> 4135.56 | AD25: 23
A26: 24 | B26: 8711 | AD26: 24
A27: 25 | B27: TENNESEE WYLIE BALETE | C27: Admin Aide I | D27: - d | E27: o- | F27: 13 | G27: 344.63 | H27: =G27*F27 -> 4480.19 | AC27: =SUM(H27:AB27) -> 4480.19 | AD27: 25
A28: 26 | B28: 8731 | AD28: 26
A29: 27 | B29: ALFREDO GONZALES | C29: Admin Aide I | D29: - d | E29: o- | F29: 12 | G29: 344.63 | H29: =G29*F29 -> 4135.56 | AC29: =SUM(H29:AB29) -> 4135.56 | AD29: 27
A30: 28 | B30: RODANTE LORENZANA | C30: Admin Aide I | D30: - d | E30: o- | F30: 11 | G30: 344.63 | H30: =G30*F30 -> 3790.93 | AC30: =SUM(H30:AB30) -> 3790.93 | AD30: 28
A31: 29 | B31: ROBERTO BRECINIO | C31: Admin Aide I | D31: - d | E31: o- | F31: 11 | G31: 344.63 | H31: =G31*F31 -> 3790.93 | AC31: =SUM(H31:AB31) -> 3790.93 | AD31: 29
A32: 30 | B32: 8751 | AD32: 30
A33: 31 | B33: MARK JOSEPH BALOTA | C33: Admin Aide I | D33: - d | E33: o- | F33: 12 | G33: 344.63 | H33: =G33*F33 -> 4135.56 | AC33: =SUM(H33:AB33) -> 4135.56 | AD33: 31
A34: 33 | B34: 8811 | AD34: 33
A35: 34 | B35: ALDRIN BUENA | C35: Admin Aide I | D35: - d | E35: o- | F35: 13 | G35: 344.63 | H35: =G35*F35 -> 4480.19 | AC35: =SUM(H35:AB35) -> 4480.19 | AD35: 34
A36: 35 | B36: JONATHAN AZULA | C36: Admin Aide I | D36: - d | E36: o- | F36: 12 | G36: 344.63 | H36: =G36*F36 -> 4135.56 | AC36: =SUM(H36:AB36) -> 4135.56 | AD36: 35
A37: 36 | B37: 8852 | AD37: 36
A38: 37 | B38: ROMANO ALMERA | C38: Admin Aide I | D38: - d | E38: o- | F38: 14 | G38: 344.63 | H38: =G38*F38 -> 4824.82 | AC38: =SUM(H38:AB38) -> 4824.82 | AD38: 37
A39: 38 | B39: NESTOR GABALENO | C39: Admin Aide I | D39: - d | E39: o- | F39: 13 | G39: 344.63 | H39: =G39*F39 -> 4480.19 | AC39: =SUM(H39:AB39) -> 4480.19 | AD39: 38
A40: 39 | B40: ERIK JAVIER | C40: Admin Aide I | D40: - d | E40: o- | F40: 14 | G40: 344.63 | H40: =G40*F40 -> 4824.82 | AC40: =SUM(H40:AB40) -> 4824.82 | AD40: 39
A41: 40 | B41: LED VENI PENIDO | C41: Admin Aide I | D41: - d | E41: o- | F41: 13 | G41: 344.63 | H41: =G41*F41 -> 4480.19 | AC41: =SUM(H41:AB41) -> 4480.19 | AD41: 40
...

Sheet JO#LDRRM
A1: Municipal P A Y R O L L
A2: WE HEREBY ACKNOWLEDGE TO HAVE RECEIVED FROM MINERVA L. BOONGALING, TREASURER OF PAGSANJAN, LAGUNA THE SUMS HEREIN SPECIFIED OPPOSITES OUR RESPECTIVE NAMES, THE SAME BEING FULL COMPENSATION FOR OUR SERVICES RENDERED DURING THE PERIOD STATED BELOW, TO THE CORRECTNESS OF WHICH WE HEREBY SEVERALLY
A4: NO. | B4: NAME | C4: DESIGNATION | D4: PERIOD OF SERVICE (INCLUSIVE DATES) | H4: AMOUNT ACCRUED FOR THE PERIOD | I4: D E D U C T I O N S
D5: FROM | E5: TO | I5: Hazard Pay | J5: SOS | K5: ESL | N5: GOVERNMENT SERVICE INSURANCE SYSTEM | AC5: AMOUNT PAID IN CASH (CR.A-1) | AD5: N U M B E R
F6: Mothly Rate | M6: EL | O6: POLICY LOAN | P6: MEDICARE | R6: LIFE/RETIREMENT | X6: GLOBE | Y6: RBP | AE6: SIGNATURE OF PAYEE | AF6: REMARKS
P7: PERSONAL SHARE | Q7: GOV'T. SHARE | R7: INSURANCE PREMIUM | V7: CAL | W7: UOLI | AB7: STATE. INSURANCE
F8: Daily Rate | G8: No. of | R8: PERSONAL SHARE | S8: GOV'T. SHARE | T8: OPTIONAL | U8: UOLI
G9: Days | I9: Nov. 2016 | Q9: Hazard
A10: 1 | B10: 2 | C10: 3 | D10: 4 | E10: 5 | F10: 6 | H10: 7 | I10: 8 | J10: 9 | K10: 10 | L10: 11 | M10: 12 | N10: 13 | O10: 12 | P10: 13 | Q10: 14 | R10: 15 | S10: 16 | T10: 17 | U10: 18 | V10: 21 | W10: 22 | X10: 23 | Y10: 24 | Z10: 19 | AA10: 20 | AB10: 21 | AC10: 22 | AD10: 23 | AE10: 24 | AF10: 25
B11: 9941 LDRRMO
A12: 1 | B12: Jerome Lava | C12: Admin Aide I | D12: March 1-15, 2017 | F12: 344.63 | G12: 13 | H12: =F12*G12 -> 4480.19 | AC12: =SUM(H12:K12) -> 4480.19 | AD12: 1
A13: 2 | B13: Rhonnie Cosio | C13: Admin Aide I | D13: - d | E13: o- | F13: 344.63 | G13: 14 | H13: =F13*G13 -> 4824.82 | AC13: =SUM(H13:K13) -> 4824.82 | AD13: 2
A14: 3 | B14: Mark Paul Monteiro | C14: Admin Aide I | D14: - d | E14: o- | F14: 344.63 | G14: 14 | H14: =F14*G14 -> 4824.82 | AC14: =SUM(H14:K14) -> 4824.82 | AD14: 3
A15: 4 | B15: Hercules Glodoveza | C15: Admin Aide I | D15: - d | E15: o- | F15: 344.63 | G15: 13 | H15: =F15*G15 -> 4480.19 | AC15: =SUM(H15:K15) -> 4480.19 | AD15: 4
A16: 6 | AD16: 6
A17: 7 | AD17: 7
A18: 8 | AD18: 8
A19: 9 | AD19: 9
A20: 10 | AD20: 10
A21: 11 | AD21: 11
A22: 12 | AD22: 12
A23: 13 | AD23: 13
A24: 14 | AD24: 14
A25: 15 | AD25: 15
A26: 16 | AD26: 16
A27: 17 | AD27: 17
A28: 18 | AD28: 18
A29: 19 | B29: TOTAL | H29: =SUM(H11:H28) -> 18610.02 | AC29: =SUM(AC11:AC28) -> 18610.02 | AD29: 19
A30: (1) I HEREBY CERTIFY on my official oath that the above PAYROLL is correct, and that services above stated have been duly rendered. Payment for such services is also hereby approved from the appropriation indicated. | I30: (4) APPROVED | AB30: (5) I HEREBY CERTIFY on my official oath that I have paid in cash to each official and employee whose name appears on the above roll the amount set opposite his name, under column 22, he having signed or marked his name under column 24 above, in my presence and at the time that payment was made to him, in acknowledgement of receipt of the money paid him.
J32: GIRLIE JAVIER EJERCITO
J33: Municipal Mayor
D34: JAY KEENSON C. ACEBUCHE | J34: Chief of Office
D35: Municipal Planning & Devt. Coordinator
A37: (2) APPROVED for payment subject to preaudit:
E39: Treasurer | AB39: (6) I HEREBY CERTIFY on my official oath that each employee whose name appears on the above roll has been paid in cash or in check, and in no other mode, the amount shown under column 22 above, opposite his name. The total of the payments made by means this payroll amount to
A41: (3) Preaudited and approved for payment in the month of
C43: (P ) | E43: pesos only.
C44: Provincial Auditor | AF44: Treasurer

Sheet JO#5%DP
A1: Municipal P A Y R O L L
A2: WE HEREBY ACKNOWLEDGE TO HAVE RECEIVED FROM MINERVA L. BOONGALING, TREASURER OF PAGSANJAN, LAGUNA THE SUMS HEREIN SPECIFIED OPPOSITES OUR RESPECTIVE NAMES, THE SAME BEING FULL COMPENSATION FOR OUR SERVICES RENDERED DURING THE PERIOD STATED BELOW, TO THE CORRECTNESS OF WHICH WE HEREBY SEVERALLY
A4: NO. | B4: NAME | C4: DESIGNATION | D4: PERIOD OF SERVICE (INCLUSIVE DATES) | H4: AMOUNT ACCRUED FOR THE PERIOD | I4: D E D U C T I O N S
D5: FROM | E5: TO | I5: Hazard Pay | J5: SOS | K5: ESL | N5: GOVERNMENT SERVICE INSURANCE SYSTEM | AC5: AMOUNT PAID IN CASH (CR.A-1) | AD5: N U M B E R
G6: Mothly Rate | M6: EL | O6: POLICY LOAN | P6: MEDICARE | R6: LIFE/RETIREMENT | X6: GLOBE | Y6: RBP | AE6: SIGNATURE OF PAYEE | AF6: REMARKS
P7: PERSONAL SHARE | Q7: GOV'T. SHARE | R7: INSURANCE PREMIUM | V7: CAL | W7: UOLI | AB7: STATE. INSURANCE
G8: Daily Rate | R8: PERSONAL SHARE | S8: GOV'T. SHARE | T8: OPTIONAL | U8: UOLI
I9: Nov. 2016 | Q9: Hazard
A10: 1 | B10: 2 | C10: 3 | D10: 4 | E10: 5 | G10: 6 | H10: 7 | I10: 8 | J10: 9 | K10: 10 | L10: 11 | M10: 12 | N10: 13 | O10: 12 | P10: 13 | Q10: 14 | R10: 15 | S10: 16 | T10: 17 | U10: 18 | V10: 21 | W10: 22 | X10: 23 | Y10: 24 | Z10: 19 | AA10: 20 | AB10: 21 | AC10: 22 | AD10: 23 | AE10: 24 | AF10: 25
A11: 2 | B11: 5% DISASTER PREPAREDNESS-Mobilization of Emergency Response Team | AD11: 2
A12: 3 | B12: RONEL CABREZA | C12: Admin Aide I | D12: March 1-15, 2017 | F12: 12 | G12: 344.63 | H12: =G12*F12 -> 4135.56 | AC12: =SUM(H12:AB12) -> 4135.56 | AD12: 3
A13: 4 | B13: VICTOR MIRANDO | C13: Admin Aide I | D13: - d | E13: o- | F13: 13 | G13: 344.63 | H13: =G13*F13 -> 4480.19 | AC13: =SUM(H13:AB13) -> 4480.19 | AD13: 4
A14: 5 | B14: RODERICK TOBIAS | C14: Admin Aide I | D14: - d | E14: o- | F14: 13 | G14: 344.63 | H14: =G14*F14 -> 4480.19 | AC14: =SUM(H14:AB14) -> 4480.19 | AD14: 5
A15: 6 | B15: NIÑO VALDELLON | C15: Admin Aide I | D15: - d | E15: o- | F15: 13 | G15: 344.63 | H15: =G15*F15 -> 4480.19 | AC15: =SUM(H15:AB15) -> 4480.19 | AD15: 6
A16: 7 | B16: JAYSON AZULA | C16: Admin Aide I | D16: - d | E16: o- | F16: 13 | G16: 344.63 | H16: =G16*F16 -> 4480.19 | AC16: =SUM(H16:AB16) -> 4480.19 | AD16: 7
A17: 9 | AD17: 9
A18: 10 | AD18: 10
A19: 11 | AD19: 11
A20: 12 | AD20: 12
A21: 13 | AD21: 13
A22: 15 | AD22: 15
A23: 17 | AD23: 17
A24: 19 | AD24: 19
A25: 20 | AD25: 20
A26: 21 | AD26: 21
A27: 22 | AD27: 22
A28: 23 | B28: Grand Total | H28: =SUM(H12:H16) -> 22056.32 | AC28: =SUM(AC12:AC16) -> 22056.32 | AD28: 23
A29: (1) I HEREBY CERTIFY on my official oath that the above PAYROLL is correct, and that services above stated have been duly rendered. Payment for such services is also hereby approved from the appropriation indicated. | I29: (4) APPROVED | AB29: (5) I HEREBY CERTIFY on my official oath that I have paid in cash to each official and employee whose name appears on the above roll the amount set opposite his name, under column 22, he having signed or marked his name under column 24 above, in my presence and at the time that payment was made to him, in acknowledgement of receipt of the money paid him.
J31: GIRLIE JAVIER EJERCITO
J32: Municipal Mayor
D33: JAY KEENSON C. ACEBUCHE | J33: Chief of Office
D34: Municipal Planning & Devt. Coordinator
A36: (2) APPROVED for payment subject to preaudit:
E38: Treasurer | AB38: (6) I HEREBY CERTIFY on my official oath that each employee whose name appears on the above roll has been paid in cash or in check, and in no other mode, the amount shown under column 22 above, opposite his name. The total of the payments made by means this payroll amount to
A40: (3) Preaudited and approved for payment in the month of
C42: (P ) | E42: pesos only.
C43: Provincial Auditor | AF43: Treasurer

Sheet JO#20%LDC
A1: Municipal P A Y R O L L
A2: WE HEREBY ACKNOWLEDGE TO HAVE RECEIVED FROM MINERVA L. BOONGALING, TREASURER OF PAGSANJAN, LAGUNA THE SUMS HEREIN SPECIFIED OPPOSITES OUR RESPECTIVE NAMES, THE SAME BEING FULL COMPENSATION FOR OUR SERVICES RENDERED DURING THE PERIOD STATED BELOW, TO THE CORRECTNESS OF WHICH WE HEREBY SEVERALLY
A4: NO. | B4: NAME | C4: DESIGNATION | D4: PERIOD OF SERVICE (INCLUSIVE DATES) | H4: AMOUNT ACCRUED FOR THE PERIOD | I4: D E D U C T I O N S
D5: FROM | E5: TO | I5: Hazard Pay | J5: SOS | K5: ESL | N5: GOVERNMENT SERVICE INSURANCE SYSTEM | AC5: AMOUNT PAID IN CASH (CR.A-1) | AD5: N U M B E R
F6: Mothly Rate | M6: EL | O6: POLICY LOAN | P6: MEDICARE | R6: LIFE/RETIREMENT | X6: GLOBE | Y6: RBP | AE6: SIGNATURE OF PAYEE | AF6: REMARKS
P7: PERSONAL SHARE | Q7: GOV'T. SHARE | R7: INSURANCE PREMIUM | V7: CAL | W7: UOLI | AB7: STATE. INSURANCE
F8: Daily Rate | G8: No. of | R8: PERSONAL SHARE | S8: GOV'T. SHARE | T8: OPTIONAL | U8: UOLI
G9: Days | I9: Nov. 2016 | Q9: Hazard
A10: 1 | B10: 2 | C10: 3 | D10: 4 | E10: 5 | F10: 6 | H10: 7 | I10: 8 | J10: 9 | K10: 10 | L10: 11 | M10: 12 | N10: 13 | O10: 12 | P10: 13 | Q10: 14 | R10: 15 | S10: 16 | T10: 17 | U10: 18 | V10: 21 | W10: 22 | X10: 23 | Y10: 24 | Z10: 19 | AA10: 20 | AB10: 21 | AC10: 22 | AD10: 23 | AE10: 24 | AF10: 25
B11: 20% LDC
B12: ALFREDO GONZALES | C12: Admin Aide I | D12: March 1-15, 2017 | F12: 344.63 | G12: 14 | H12: =F12*14 -> 4824.82 | AC12: =SUM(H12:AB12) -> 4824.82
B13: RODANTE LORENZANA | C13: Admin Aide I | D13: - d | E13: o- | F13: 344.63 | G13: 14 | H13: =F13*14 -> 4824.82 | AC13: =SUM(H13:AB13) -> 4824.82
B14: RAMON WAPERINA | C14: Admin Aide I | D14: - d | E14: o- | F14: 344.63 | G14: 14 | H14: =F14*14 -> 4824.82 | AC14: =SUM(H14:AB14) -> 4824.82
B15: ROBERTO BRECINIO | C15: Admin Aide I | D15: - d | E15: o- | F15: 344.63 | G15: 10 | H15: =F15*10 -> 3446.3 | AC15: =SUM(H15:AB15) -> 3446.3
A23: 13 | AD23: 13
A24: 14 | AD24: 14
A25: 15 | AD25: 15
A26: 16 | AD26: 16
A27: 17 | AD27: 17
A28: 18 | AD28: 18
A29: 19 | AD29: 19
A30: 20 | AD30: 20
A31: 21 | AD31: 21
A32: 22 | AD32: 22
A33: 23 | AD33: 23
A34: 24 | AD34: 24
A35: 25 | AD35: 25
A36: 26 | B36: TOTAL | H36: =SUM(H11:H35) -> 17920.76 | AC36: =SUM(AC11:AC34) -> 17920.76 | AD36: 26
A37: (1) I HEREBY CERTIFY on my official oath that the above PAYROLL is correct, and that services above stated have been duly rendered. Payment for such services is also hereby approved from the appropriation indicated. | I37: (4) APPROVED | AB37: (5) I HEREBY CERTIFY on my official oath that I have paid in cash to each official and employee whose name appears on the above roll the amount set opposite his name, under column 22, he having signed or marked his name under column 24 above, in my presence and at the time that payment was made to him, in acknowledgement of receipt of the money paid him.
J39: GIRLIE JAVIER EJERCITO
J40: Municipal Mayor
D41: FLORANTE C. SALVADOR JR. | J41: Chief of Office
D42: Municipal Administrator
A44: (2) APPROVED for payment subject to preaudit:
E46: Treasurer | AB46: (6) I HEREBY CERTIFY on my official oath that each employee whose name appears on the above roll has been paid in cash or in check, and in no other mode, the amount shown under column 22 above, opposite his name. The total of the payments made by means this payroll amount to
A48: (3) Preaudited and approved for payment in the month of
C50: (P ) | E50: pesos only.
C51: Provincial Auditor | AF51: Treasurer

Sheet JO#20%DF
A1: Municipal P A Y R O L L
A2: WE HEREBY ACKNOWLEDGE TO HAVE RECEIVED FROM MINERVA L. BOONGALING, TREASURER OF PAGSANJAN, LAGUNA THE SUMS HEREIN SPECIFIED OPPOSITES OUR RESPECTIVE NAMES, THE SAME BEING FULL COMPENSATION FOR OUR SERVICES RENDERED DURING THE PERIOD STATED BELOW, TO THE CORRECTNESS OF WHICH WE HEREBY SEVERALLY
A4: NO. | B4: NAME | C4: DESIGNATION | D4: PERIOD OF SERVICE (INCLUSIVE DATES) | H4: AMOUNT ACCRUED FOR THE PERIOD | I4: D E D U C T I O N S
D5: FROM | E5: TO | I5: Hazard Pay | J5: SOS | K5: ESL | N5: GOVERNMENT SERVICE INSURANCE SYSTEM | AC5: AMOUNT PAID IN CASH (CR.A-1) | AD5: N U M B E R
F6: Mothly Rate | M6: EL | O6: POLICY LOAN | P6: MEDICARE | R6: LIFE/RETIREMENT | X6: GLOBE | Y6: RBP | AE6: SIGNATURE OF PAYEE | AF6: REMARKS
P7: PERSONAL SHARE | Q7: GOV'T. SHARE | R7: INSURANCE PREMIUM | V7: CAL | W7: UOLI | AB7: STATE. INSURANCE
F8: Daily Rate | G8: No. of | R8: PERSONAL SHARE | S8: GOV'T. SHARE | T8: OPTIONAL | U8: UOLI
G9: Days | I9: Nov. 2016 | Q9: Hazard
A10: 1 | B10: 2 | C10: 3 | D10: 4 | E10: 5 | F10: 6 | H10: 7 | I10: 8 | J10: 9 | K10: 10 | L10: 11 | M10: 12 | N10: 13 | O10: 12 | P10: 13 | Q10: 14 | R10: 15 | S10: 16 | T10: 17 | U10: 18 | V10: 21 | W10: 22 | X10: 23 | Y10: 24 | Z10: 19 | AA10: 20 | AB10: 21 | AC10: 22 | AD10: 23 | AE10: 24 | AF10: 25
B11: 20% DEVELOPMENT FUND-Solid Waste Management Environmental Services
A12: 1 | B12: ALBERT ELCA | C12: Admin Aide I | D12: March 1-15, 2017 | F12: 344.63 | G12: 13 | H12: =F12*G12 -> 4480.19 | AC12: =SUM(H12:K12) -> 4480.19 | AD12: 1
A13: 2 | B13: RICHARD MONTESUR | C13: Admin Aide I | D13: - d | E13: o- | F13: 344.63 | G13: 11 | H13: =F13*G13 -> 3790.93 | AC13: =SUM(H13:K13) -> 3790.93 | AD13: 2
A14: 3 | B14: RAMON WAPERINA | C14: Admin Aide I | D14: - d | E14: o- | F14: 344.63 | G14: 15 | H14: =F14*G14 -> 5169.45 | AC14: =SUM(H14:K14) -> 5169.45 | AD14: 3
A15: 4 | B15: RIVERA ANGELO | C15: Admin Aide I | D15: - d | E15: o- | F15: 344.63 | G15: 13 | H15: =F15*G15 -> 4480.19 | AC15: =SUM(H15:K15) -> 4480.19 | AD15: 4
A16: 5 | B16: NOEL ABEGONZA | C16: Admin Aide I | D16: - d | E16: o- | F16: 344.63 | G16: 13 | H16: =F16*G16 -> 4480.19 | AC16: =SUM(H16:K16) -> 4480.19 | AD16: 5
A17: 6 | AD17: 6
A18: 7 | AD18: 7
A19: 8 | AD19: 8
A20: 9 | AD20: 9
A21: 10 | AD21: 10
A22: 11 | AD22: 11
A23: 12 | AD23: 12
A24: 13 | AD24: 13
A25: 14 | AD25: 14
A26: 15 | AD26: 15
A27: 16 | AD27: 16
A28: 17 | AD28: 17
A29: 18 | AD29: 18
A30: 19 | B30: TOTAL | H30: =SUM(H11:H29) -> 22400.95 | AC30: =SUM(AC11:AC29) -> 22400.95 | AD30: 19
A31: (1) I HEREBY CERTIFY on my official oath that the above PAYROLL is correct, and that services above stated have been duly rendered. Payment for such services is also hereby approved from the appropriation indicated. | I31: (4) APPROVED | AB31: (5) I HEREBY CERTIFY on my official oath that I have paid in cash to each official and employee whose name appears on the above roll the amount set opposite his name, under column 22, he having signed or marked his name under column 24 above, in my presence and at the time that payment was made to him, in acknowledgement of receipt of the money paid him.
J33: GIRLIE JAVIER EJERCITO
J34: Municipal Mayor
D35: JAY KEENSON C. ACEBUCHE | J35: Chief of Office
D36: Municipal Planning & Devt. Coordinator
A38: (2) APPROVED for payment subject to preaudit:
E40: Treasurer | AB40: (6) I HEREBY CERTIFY on my official oath that each employee whose name appears on the above roll has been paid in cash or in check, and in no other mode, the amount shown under column 22 above, opposite his name. The total of the payments made by means this payroll amount to
A42: (3) Preaudited and approved for payment in the month of
C44: (P ) | E44: pesos only.
C45: Provincial Auditor | AF45: Treasurer

Sheet JO#MHO
A1: Municipal P A Y R O L L
A2: WE HEREBY ACKNOWLEDGE TO HAVE RECEIVED FROM MINERVA L. BOONGALING, TREASURER OF PAGSANJAN, LAGUNA THE SUMS HEREIN SPECIFIED OPPOSITES OUR RESPECTIVE NAMES, THE SAME BEING FULL COMPENSATION FOR OUR SERVICES RENDERED DURING THE PERIOD STATED BELOW, TO THE CORRECTNESS OF WHICH WE HEREBY SEVERALLY
A4: NO. | B4: NAME | C4: DESIGNATION | D4: PERIOD OF SERVICE (INCLUSIVE DATES) | H4: AMOUNT ACCRUED FOR THE PERIOD | I4: D E D U C T I O N S
D5: FROM | E5: TO | I5: Hazard Pay | J5: SOS | K5: ESL | N5: GOVERNMENT SERVICE INSURANCE SYSTEM | AC5: AMOUNT PAID IN CASH (CR.A-1) | AD5: N U M B E R
F6: Mothly Rate | M6: EL | O6: POLICY LOAN | P6: MEDICARE | R6: LIFE/RETIREMENT | X6: GLOBE | Y6: RBP | AE6: SIGNATURE OF PAYEE | AF6: REMARKS
P7: PERSONAL SHARE | Q7: GOV'T. SHARE | R7: INSURANCE PREMIUM | V7: CAL | W7: UOLI | AB7: STATE. INSURANCE
F8: Daily Rate | G8: No. of | R8: PERSONAL SHARE | S8: GOV'T. SHARE | T8: OPTIONAL | U8: UOLI
G9: Days | I9: Mar | Q9: Hazard
A10: 1 | B10: 2 | C10: 3 | D10: 4 | E10: 5 | F10: 6 | H10: 7 | I10: 8 | J10: 9 | K10: 10 | L10: 11 | M10: 12 | N10: 13 | O10: 12 | P10: 13 | Q10: 14 | R10: 15 | S10: 16 | T10: 17 | U10: 18 | V10: 21 | W10: 22 | X10: 23 | Y10: 24 | Z10: 19 | AA10: 20 | AB10: 21 | AC10: 22 | AD10: 23 | AE10: 24 | AF10: 25
A11: 1 | B11: 4411 | D11: Mar. 1-15, 2017 | AD11: 1
A12: 2 | B12: REGGIE PACHECO | C12: Admin Aide I | D12: - d | E12: o- | F12: 430.82 | G12: 12 | H12: =F12*G12 -> 5169.84 | AC12: =SUM(H12:K12) -> 5169.84 | AD12: 2
A13: 3 | B13: GLORIANA ELIS B. GOMA | C13: Admin Aide I | D13: - d | E13: o- | F13: 430.82 | G13: 12 | H13: =F13*G13 -> 5169.84 | I13: 1270.5 | AC13: =SUM(H13:K13) -> 6440.34 | AD13: 3
A14: 4 | B14: ZHALEE MARIE BALETE | C14: Admin Aide I | D14: - d | E14: o- | F14: 430.82 | G14: 14 | H14: =F14*G14 -> 6031.48 | I14: 1270.5 | AC14: =SUM(H14:K14) -> 7301.98 | AD14: 4
A15: 5 | B15: SNOOKY ENSINAS | C15: Admin Aide I | D15: - d | E15: o- | F15: 430.82 | G15: 13 | H15: =F15*G15 -> 5600.66 | I15: 1270.5 | AC15: =SUM(H15:K15) -> 6871.16 | AD15: 5
A16: 6 | B16: MARIA YSOBELLE CABALLES | C16: Admin Aide I | D16: - d | E16: o- | F16: 430.82 | G16: 12 | H16: =F16*G16 -> 5169.84 | I16: 1270.5 | AC16: =SUM(H16:K16) -> 6440.34 | AD16: 6
A17: 7 | B17: MARY JANE ONGSANSOY | C17: Admin Aide I | D17: - d | E17: o- | F17: 430.82 | G17: 13 | H17: =F17*G17 -> 5600.66 | I17: 1270.5 | AC17: =SUM(H17:K17) -> 6871.16 | AD17: 7
A18: 8 | B18: RAMIL ABLIR | C18: Admin Aide I | D18: - d | E18: o- | F18: 430.82 | G18: 12 | H18: =F18*G18 -> 5169.84 | AC18: =SUM(H18:K18) -> 5169.84 | AD18: 8
A19: 9 | AD19: 9
A20: 10 | AD20: 10
A21: 11 | AD21: 11
A22: 13 | AD22: 13
A23: 14 | AD23: 14
A24: 15 | AD24: 15
A25: 23 | AD25: 23
A26: 24 | AD26: 24
A27: 26 | B27: TOTAL | H27: =SUM(H12:H26) -> 37912.16 | I27: =SUM(I12:I26) -> 6352.5 | AC27: =SUM(AC11:AC26) -> 44264.66 | AD27: 26
A28: (1) I HEREBY CERTIFY on my official oath that the above PAYROLL is correct, and that services above stated have been duly rendered. Payment for such services is also hereby approved from the appropriation indicated. | I28: (4) APPROVED | AB28: (5) I HEREBY CERTIFY on my official oath that I have paid in cash to each official and employee whose name appears on the above roll the amount set opposite his name, under column 22, he having signed or marked his name under column 24 above, in my presence and at the time that payment was made to him, in acknowledgement of receipt of the money paid him.
J30: GIRLIE JAVIER EJERCITO
J31: Municipal Mayor
D32: DR. LYRA LERON TORRES | J32: Chief of Office
D33: Municipal Health Officer
A35: (2) APPROVED for payment subject to preaudit:
E37: Treasurer | AB37: (6) I HEREBY CERTIFY on my official oath that each employee whose name appears on the above roll has been paid in cash or in check, and in no other mode, the amount shown under column 22 above, opposite his name. The total of the payments made by means this payroll amount to
A39: (3) Preaudited and approved for payment in the month of
C41: (P ) | E41: pesos only.
C42: Provincial Auditor | AF42: Treasurer

Sheet JO#SB
A1: Municipal P A Y R O L L
A2: WE HEREBY ACKNOWLEDGE TO HAVE RECEIVED FROM MINERVA L. BOONGALING, TREASURER OF PAGSANJAN, LAGUNA THE SUMS HEREIN SPECIFIED OPPOSITES OUR RESPECTIVE NAMES, THE SAME BEING FULL COMPENSATION FOR OUR SERVICES RENDERED DURING THE PERIOD STATED BELOW, TO THE CORRECTNESS OF WHICH WE HEREBY SEVERALLY
A4: NO. | B4: NAME | C4: DESIGNATION | D4: PERIOD OF SERVICE (INCLUSIVE DATES) | H4: AMOUNT ACCRUED FOR THE PERIOD | I4: D E D U C T I O N S
D5: FROM | E5: TO | I5: Hazard Pay | J5: SOS | K5: ESL | N5: GOVERNMENT SERVICE INSURANCE SYSTEM | AC5: AMOUNT PAID IN CASH (CR.A-1) | AD5: N U M B E R
F6: Mothly Rate | M6: EL | O6: POLICY LOAN | P6: MEDICARE | R6: LIFE/RETIREMENT | X6: GLOBE | Y6: RBP | AE6: SIGNATURE OF PAYEE | AF6: REMARKS
P7: PERSONAL SHARE | Q7: GOV'T. SHARE | R7: INSURANCE PREMIUM | V7: CAL | W7: UOLI | AB7: STATE. INSURANCE
F8: Daily Rate | G8: No. of | R8: PERSONAL SHARE | S8: GOV'T. SHARE | T8: OPTIONAL | U8: UOLI
G9: Days | I9: Nov. 2016 | Q9: Hazard
A10: 1 | B10: 2 | C10: 3 | D10: 4 | E10: 5 | F10: 6 | H10: 7 | I10: 8 | J10: 9 | K10: 10 | L10: 11 | M10: 12 | N10: 13 | O10: 12 | P10: 13 | Q10: 14 | R10: 15 | S10: 16 | T10: 17 | U10: 18 | V10: 21 | W10: 22 | X10: 23 | Y10: 24 | Z10: 19 | AA10: 20 | AB10: 21 | AC10: 22 | AD10: 23 | AE10: 24 | AF10: 25
B11: 1016
A12: 1 | B12: NORMAN V. NICANDRO | C12: Admin Aide I | D12: March 1-15, 2017 | F12: 344.63 | G12: 12 | H12: =F12*G12 -> 4135.56 | AC12: =SUM(H12:AB12) -> 4135.56
A13: 2 | B13: MARILIZ M. TRINIDAD | C13: Admin Aide I | D13: - d | E13: o- | F13: 344.63 | G13: 7 | H13: =F13*G13 -> 2412.41 | AC13: =SUM(H13:AB13) -> 2412.41
B14: 1021
A15: 3 | B15: ANDRES H. SIERRAS | C15: Admin Aide I | D15: - d | E15: o- | F15: 344.63 | G15: 12 | H15: =F15*G15 -> 4135.56 | AC15: =SUM(H15:AB15) -> 4135.56
B29: TOTAL | H29: =SUM(H11:H28) -> 10683.53 | AC29: =SUM(AC11:AC28) -> 10683.53
A30: (1) I HEREBY CERTIFY on my official oath that the above PAYROLL is correct, and that services above stated have been duly rendered. Payment for such services is also hereby approved from the appropriation indicated. | I30: (4) APPROVED | AB30: (5) I HEREBY CERTIFY on my official oath that I have paid in cash to each official and employee whose name appears on the above roll the amount set opposite his name, under column 22, he having signed or marked his name under column 24 above, in my presence and at the time that payment was made to him, in acknowledgement of receipt of the money paid him.
J32: DR. PETER CASIUS M. TRINIDAD
J33: Municipal Vice Mayor
D34: DR. PETER CASIUS M. TRINIDAD | J34: Chief of Office
D35: Municipal Vice Mayor
A37: (2) APPROVED for payment subject to preaudit:
E39: Treasurer | AB39: (6) I HEREBY CERTIFY on my official oath that each employee whose name appears on the above roll has been paid in cash or in check, and in no other mode, the amount shown under column 22 above, opposite his name. The total of the payments made by means this payroll amount to
A41: (3) Preaudited and approved for payment in the month of
C43: (P ) | E43: pesos only.
C44: Provincial Auditor | AF44: Treasurer

Sheet Casual allow SB
A1: Municipal P A Y R O L L
A2: WE HEREBY ACKNOWLEDGE TO HAVE RECEIVED FROM MINERVA L. BOONGALING, TREASURER OF PAGSANJAN, LAGUNA THE SUMS HEREIN SPECIFIED OPPOSITES OUR RESPECTIVE NAMES, THE SAME BEING FULL COMPENSATION FOR OUR SERVICES RENDERED DURING THE PERIOD STATED BELOW, TO THE CORRECTNESS OF WHICH WE HEREBY SEVERALLY
A4: NO. | B4: NAME | C4: DESIGNATION | D4: PERIOD OF SERVICE (INCLUSIVE DATES) | G4: AMOUNT ACCRUED FOR THE PERIOD | H4: D E D U C T I O N S
D5: FROM | E5: TO | H5: LAUNDRY | I5: HAZARD PAY | J5: SUBSISTENCE | K5: EL | L5: GOVERNMENT SERVICE INSURANCE SYSTEM | X5: Pag Ibig | AA5: AMOUNT PAID IN CASH (CR.A-1) | AB5: N U M B E R
F6: MONTLY RATE OF PAY | L6: CONSOL | M6: POLICY LOAN | N6: PHILHEALTH | P6: LIFE/RETIREMENT | V6: GLOBE | W6: RBP | AC6: SIGNATURE OF PAYEE | AD6: REMARKS
N7: PERSONAL SHARE | O7: GOV'T. SHARE | P7: INSURANCE PREMIUM | T7: CAL | U7: EDU. CHILD | Z7: STATE. INSURANCE
P8: PERSONAL SHARE | Q8: GOVERNMENT SHARE | R8: OPTIONAL | S8: Educ
X9: MPL | Y9: CALAMITY
A10: 1 | B10: 2 | C10: 3 | D10: 4 | E10: 5 | F10: 6 | G10: 7 | H10: 8 | I10: 8 | J10: 9 | K10: 10 | L10: 11 | M10: 12 | N10: 13 | O10: 14 | P10: 15 | Q10: 17 | R10: 18 | S10: 20 | T10: 21 | U10: 22 | V10: 23 | W10: 24 | X10: 25 | Y10: 26 | Z10: 19 | AA10: 20 | AB10: 21 | AC10: 22 | AD10: 23
A11: 1 | AB11: 1
A12: 2 | B12: 1016-1021-1022 | AB12: 2
A13: 3 | B13: JOWEL PALACOL | C13: Admin Aide I | D13: March 2017 | G13: 2000 | AA13: =G13 -> 2000 | AB13: 3
A14: 4 | B14: MARVIN PINILI | C14: Admin Aide I | D14: -do- | G14: 2000 | AA14: =G14 -> 2000 | AB14: 4
A15: 5 | B15: NOWEL LERON | C15: Admin Aide I | D15: -do- | G15: 2000 | AA15: =G15 -> 2000 | AB15: 5
A16: 6 | AB16: 6
A17: 7 | AB17: 7
A18: 8 | AB18: 8
A19: 9 | AB19: 9
A20: 10 | AB20: 10
A21: 11 | AB21: 11
A22: 12 | AB22: 12
A23: 13 | AB23: 13
A24: 14 | AB24: 14
A25: 15 | AB25: 15
A26: 16 | AB26: 16
A27: 17 | G27: =SUM(G13:G26) -> 6000 | I27: =#REF! -> #REF! | AA27: =SUM(AA13:AA26) -> 6000 | AB27: 17
A29: (1) I HEREBY CERTIFY on my official oath that the above PAYROLL is correct, and that services above stated have been duly rendered. Payment for such services is also hereby approved from the appropriation indicated. | M29: APPROVED:
Z30: (5) I HEREBY CERTIFY on my official oath that I have paid in cash to each official and employee whose name appears on the above roll the amount set opposite his name, under column 28, he having signed or marked his name under column 30 above, in my presence and at the time that payment was made to him, in acknowledgement of receipt of the money paid him.
K31: (4) APPROVED
N32: PETER CASIUS M. TRINIDAD
N33: Municipal Vice Mayor
D34: PETER CASIUS M. TRINIDAD | N34: Chief of Office
D35: Municipal Vice Mayor
A37: (2) APPROVED for payment subject to preaudit: | Z37: (6) I HEREBY CERTIFY on my official oath that each employee whose name appears on the above roll has been paid in cash or in check, and in no other mode, the amount shown under column 21 above, opposite his name. The total of the payments made by means this payroll amount to
E39: Treasurer
A40: (3) Preaudited and approved for payment in the month of
C41: (P ) | E41: pesos only. | AD41: Treasurer

Sheet Casual allow
A1: Municipal P A Y R O L L
A2: WE HEREBY ACKNOWLEDGE TO HAVE RECEIVED FROM MINERVA L. BOONGALING, TREASURER OF PAGSANJAN, LAGUNA THE SUMS HEREIN SPECIFIED OPPOSITES OUR RESPECTIVE NAMES, THE SAME BEING FULL COMPENSATION FOR OUR SERVICES RENDERED DURING THE PERIOD STATED BELOW, TO THE CORRECTNESS OF WHICH WE HEREBY SEVERALLY
A4: NO. | B4: NAME | C4: DESIGNATION | D4: PERIOD OF SERVICE (INCLUSIVE DATES) | G4: AMOUNT ACCRUED FOR THE PERIOD | H4: D E D U C T I O N S
D5: FROM | E5: TO | H5: LAUNDRY | I5: HAZARD PAY | J5: SUBSISTENCE | K5: EL | M5: GOVERNMENT SERVICE INSURANCE SYSTEM | Y5: Pag Ibig | AB5: AMOUNT PAID IN CASH (CR.A-1) | AC5: N U M B E R
F6: MONTLY RATE OF PAY | M6: CONSOL | N6: POLICY LOAN | O6: PHILHEALTH | Q6: LIFE/RETIREMENT | W6: GLOBE | X6: RBP | AD6: SIGNATURE OF PAYEE | AE6: REMARKS
O7: PERSONAL SHARE | P7: GOV'T. SHARE | Q7: INSURANCE PREMIUM | U7: CAL | V7: EDU. CHILD | AA7: STATE. INSURANCE
Q8: PERSONAL SHARE | R8: GOVERNMENT SHARE | S8: OPTIONAL | T8: Educ
Y9: MPL | Z9: CALAMITY
A10: 1 | B10: 2 | C10: 3 | D10: 4 | E10: 5 | F10: 6 | G10: 7 | H10: 8 | I10: 9 | J10: 10 | K10: 11 | L10: 12 | M10: 13 | N10: 14 | O10: 15 | P10: 16 | Q10: 17 | R10: 18 | S10: 19 | T10: 20 | U10: 21 | V10: 22 | W10: 23 | X10: 24 | Y10: 25 | Z10: 26 | AA10: 27 | AB10: 28 | AC10: 29 | AD10: 30 | AE10: 31
A11: 1 | B11: 1011 | AC11: 1
A12: 2 | B12: LORELIE G. LAZARO | C12: Admin Aide I | D12: 42736 | G12: 2000 | AB12: =G12 -> 2000 | AC12: 2
A13: 3 | B13: MICHAEL FRANCIS PAILAN | C13: Admin Aide I | D13: -do- | G13: 2000 | AB13: =G13 -> 2000 | AC13: 3
A14: 4 | B14: DANIEL BUNGABONG | C14: Admin Aide I | D14: -do- | G14: 2000 | AB14: =G14 -> 2000 | AC14: 4
A15: 5 | B15: JUVY GRACE DB ABARQUEZ | C15: Admin Aide I | D15: -do- | G15: 2000 | AB15: =G15 -> 2000 | AC15: 5
A16: 6 | G16: =SUM(G12:G15) -> 8000 | H16: 0 | I16: 0 | J16: 0 | K16: 0 | L16: 0 | M16: 0 | N16: 0 | O16: 0 | P16: 0 | Q16: 0 | R16: 0 | S16: 0 | T16: 0 | U16: 0 | V16: 0 | W16: 0 | X16: 0 | Y16: 0 | Z16: 0 | AA16: 0 | AB16: =SUM(AB12:AB15) -> 8000 | AC16: 6
A17: 7 | B17: 1031 | AC17: 7
A18: 8 | B18: MELAROSE PABILONIA | C18: Admin Aide I | D18: -do- | G18: 2000 | H18: 0 | K18: 0 | AB18: =G18 -> 2000 | AC18: 8
A19: 9 | G19: 2000 | H19: 0 | I19: 0 | J19: 0 | K19: 0 | L19: 0 | M19: 0 | N19: 0 | O19: 0 | P19: 0 | Q19: 0 | R19: 0 | S19: 0 | T19: 0 | U19: 0 | V19: 0 | W19: 0 | X19: 0 | Y19: 0 | Z19: 0 | AA19: 0 | AB19: 2000 | AC19: 9
A20: 10 | B20: 1032 | AC20: 10
A21: 11 | C21: Admin Aide I | D21: -do- | G21: 0 | H21: 0 | K21: 0 | M21: 0 | N21: 0 | AB21: =G21 -> 0 | AC21: 11
A22: 12 | G22: 0 | H22: 0 | I22: 0 | J22: 0 | K22: 0 | L22: 0 | M22: 0 | N22: 0 | O22: 0 | P22: 0 | Q22: 0 | R22: 0 | S22: 0 | T22: 0 | U22: 0 | V22: 0 | W22: 0 | X22: 0 | Y22: 0 | Z22: 0 | AA22: 0 | AB22: 0 | AC22: 12
A23: 13 | B23: 1071 | AC23: 13
A24: 14 | B24: MICHELLE CASTILLO | C24: Admin Aide I | D24: -do- | G24: 2000 | H24: 0 | AB24: =G24 -> 2000 | AC24: 14
A25: 15 | B25: ALVIN VILLANUEVA | C25: Admin Aide I | D25: -do- | G25: 2000 | H25: 0 | K25: 0 | M25: 0 | N25: 0 | AB25: =G25 -> 2000 | AC25: 15
A26: 16 | G26: =SUM(G24:G25) -> 4000 | H26: 0 | I26: 0 | J26: 0 | K26: 0 | L26: 0 | M26: 0 | N26: 0 | O26: 0 | P26: 0 | Q26: 0 | R26: 0 | S26: 0 | T26: 0 | U26: 0 | V26: 0 | W26: 0 | X26: 0 | Y26: 0 | Z26: 0 | AA26: 0 | AB26: =SUM(AB24:AB25) -> 4000 | AC26: 16
A27: 17 | B27: 1081 | AC27: 17
A28: 18 | B28: JOANA PATRIZHA MERAMBEL | C28: Admin Aide I | D28: -do- | G28: 2000 | H28: 0 | AB28: =G28 -> 2000 | AC28: 18
A29: 19 | B29: FELVIC Z. QUIZON | C29: Admin Aide I | D29: -do- | G29: 2000 | H29: 0 | AB29: =G29 -> 2000 | AC29: 19
A30: 20 | B30: TAMMY O. BENELADA | C30: Admin Aide I | D30: -do- | G30: 2000 | AB30: =G30 -> 2000 | AC30: 20
A31: 21 | B31: RIZALINO DE CASTRO | C31: Admin Aide I | D31: -do- | G31: 2000 | H31: 0 | AB31: =G31 -> 2000 | AC31: 21
A32: 22 | B32: FRENZIE GARANTUZA | C32: Admin Aide I | D32: -do- | G32: 2000 | H32: 0 | AB32: =G32 -> 2000 | AC32: 22
A33: 23 | G33: =SUM(G28:G32) -> 10000 | H33: 0 | I33: 0 | J33: 0 | K33: 0 | L33: 0 | M33: 0 | N33: 0 | O33: 0 | P33: 0 | Q33: 0 | R33: 0 | S33: 0 | T33: 0 | U33: 0 | V33: 0 | W33: 0 | X33: 0 | Y33: 0 | Z33: 0 | AA33: 0 | AB33: =SUM(AB28:AB32) -> 10000 | AC33: 23
A34: 24 | B34: 1091 | AC34: 24
A35: 25 | B35: JACQUILOU DIMARANAN | C35: Admin Aide I | D35: -do- | G35: 2000 | H35: 0 | AB35: =G35 -> 2000 | AC35: 25
A36: 26 | B36: NIÑO LAGRIMAS | C36: Admin Aide I | D36: -do- | G36: 2000 | H36: 0 | AB36: =G36 -> 2000 | AC36: 26
A37: 27 | B37: CHRISTIAN ABRANTES | C37: Admin Aide I | D37: -do- | G37: 2000 | H37: 0 | AB37: =G37 -> 2000 | AC37: 27
A38: 28 | B38: ARLENE JAVIER | C38: Admin Aide I | D38: -do- | G38: 2000 | H38: 0 | AB38: =G38 -> 2000 | AC38: 28
A39: 29 | G39: =SUM(G35:G38) -> 8000 | H39: 0 | I39: 0 | J39: 0 | K39: 0 | L39: 0 | M39: 0 | N39: 0 | O39: 0 | P39: 0 | Q39: 0 | R39: 0 | S39: 0 | T39: 0 | U39: 0 | V39: 0 | W39: 0 | X39: 0 | Y39: 0 | Z39: 0 | AA39: 0 | AB39: =SUM(AB35:AB38) -> 8000 | AC39: 29
A40: 30 | B40: 1101 | AC40: 30
A41: 31 | B41: ARLENE RIVERA | C41: Admin Aide I | D41: -do- | G41: 2000 | H41: 0 | K41: 0 | AB41: =G41 -> 2000 | AC41: 31
...

Sheet CasualMHO1-15
A1: Municipal P A Y R O L L
A2: WE HEREBY ACKNOWLEDGE TO HAVE RECEIVED FROM MINERVA L. BOONGALING, TREASURER OF PAGSANJAN, LAGUNA THE SUMS HEREIN SPECIFIED OPPOSITES OUR RESPECTIVE NAMES, THE SAME BEING FULL COMPENSATION FOR OUR SERVICES RENDERED DURING THE PERIOD STATED BELOW, TO THE CORRECTNESS OF WHICH WE HEREBY SEVERALLY
A4: NO. | B4: NAME | C4: DESIGNATION | D4: PERIOD OF SERVICE (INCLUSIVE DATES) | H4: AMOUNT ACCRUED FOR THE PERIOD | I4: D E D U C T I O N S
D5: FROM | E5: TO | I5: HOUSING LOAN | J5: SOS | K5: ESL | L5: EL | N5: GOVERNMENT SERVICE INSURANCE SYSTEM | Z5: Pag Ibig | AC5: AMOUNT PAID IN CASH (CR.A-1) | AD5: N U M B E R
G6: MONTLY RATE OF PAY | N6: CONSOL | O6: POLICY LOAN | P6: PHILHEALTH | R6: LIFE/RETIREMENT | X6: GLOBE | Y6: RBP | AE6: SIGNATURE OF PAYEE | AF6: REMARKS
F7: No. of days | P7: PERSONAL SHARE | Q7: GOV'T. SHARE | R7: INSURANCE PREMIUM | V7: CAL | W7: EDU. CHILD | AB7: STATE. INSURANCE
R8: PERSONAL SHARE | S8: GOVERNMENT SHARE | T8: OPTIONAL | U8: Educ
Z9: MPL | AA9: CALAMITY
A10: 1 | B10: 2 | C10: 3 | D10: 4 | E10: 5 | G10: 6 | H10: 7 | I10: 8 | J10: 9 | K10: 10 | L10: 11 | M10: 12 | N10: 13 | O10: 14 | P10: 15 | Q10: 16 | R10: 17 | S10: 18 | T10: 19 | U10: 20 | V10: 21 | W10: 22 | X10: 23 | Y10: 24 | Z10: 25 | AA10: 26 | AB10: 27 | AC10: 28 | AD10: 29 | AE10: 30 | AF10: 31
B12: 4411
A13: 1 | B13: LYKA NADERA | C13: Admin Aide I | D13: Mar. 1-15, 2017 | F13: 12 | G13: 430.82 | H13: =G13*F13 -> 5169.84 | I13: 0 | L13: 0 | N13: 0 | O13: 0 | P13: 112.5 | Q13: =P13 -> 112.5 | R13: =ROUND((G13*22)*0.09,2) -> 853.02 | S13: =ROUND(G13*22*0.12,2) -> 1137.36 | AB13: 94.78 | AC13: =H13-(SUM(I13:P13)+R13+SUM(T13:AA13)) -> 4204.32 | AD13: 1
A14: 2 | B14: HERMINIO WATSHON | C14: Admin Aide I | D14: -do- | F14: 13 | G14: 430.82 | H14: =G14*F14 -> 5600.66 | I14: 0 | L14: 0 | N14: 0 | O14: 0 | P14: 112.5 | Q14: =P14 -> 112.5 | R14: =ROUND((G14*22)*0.09,2) -> 853.02 | S14: =ROUND(G14*22*0.12,2) -> 1137.36 | T14: 0 | U14: 0 | V14: 0 | Z14: 0 | AA14: 0 | AB14: 94.78 | AC14: =H14-(SUM(I14:P14)+R14+SUM(T14:AA14)) -> 4635.14 | AD14: 2
H25: =SUM(H13:H24) -> 10770.5 | P25: =SUM(P13:P24) -> 225 | Q25: =SUM(Q13:Q24) -> 225 | R25: =SUM(R13:R24) -> 1706.04 | S25: =SUM(S13:S24) -> 2274.72 | AB25: =SUM(AB13:AB24) -> 189.56 | AC25: =SUM(AC13:AC24) -> 8839.46
AB28: (5) I HEREBY CERTIFY on my official oath that I have paid in cash to each official and employee whose name appears on the above roll the amount set opposite his name, under column 28, he having signed or marked his name under column 30 above, in my presence and at the time that payment was made to him, in acknowledgement of receipt of the money paid him.
A29: (1) I HEREBY CERTIFY on my official oath that the above PAYROLL is correct, and that services above stated have been duly rendered. Payment for such services is also hereby approved from the appropriation indicated. | I29: (4) APPROVED
J31: GIRLIE JAVIER EJERCITO
J32: Municipal Mayor
D33: DR. LYRA LERON TORRES | J33: Chief of Office
D34: Municipal Health Officer
A36: (2) APPROVED for payment subject to preaudit: | AB36: (6) I HEREBY CERTIFY on my official oath that each employee whose name appears on the above roll has been paid in cash or in check, and in no other mode, the amount shown under column 21 above, opposite his name. The total of the payments made by means this payroll amount to
E38: Treasurer
A39: (3) Preaudited and approved for payment in the month of
C40: (P ) | E40: pesos only. | AF40: Treasurer

Sheet CasualMTO16-31
A1: Municipal P A Y R O L L
A2: WE HEREBY ACKNOWLEDGE TO HAVE RECEIVED FROM MINERVA L. BOONGALING, TREASURER OF PAGSANJAN, LAGUNA THE SUMS HEREIN SPECIFIED OPPOSITES OUR RESPECTIVE NAMES, THE SAME BEING FULL COMPENSATION FOR OUR SERVICES RENDERED DURING THE PERIOD STATED BELOW, TO THE CORRECTNESS OF WHICH WE HEREBY SEVERALLY
A4: NO. | B4: NAME | C4: DESIGNATION | D4: PERIOD OF SERVICE (INCLUSIVE DATES) | H4: AMOUNT ACCRUED FOR THE PERIOD | I4: D E D U C T I O N S
D5: FROM | E5: TO | I5: Withholding Tax | J5: SOS | K5: ESL | L5: EL | N5: GOVERNMENT SERVICE INSURANCE SYSTEM | AA5: PAG-IBIG | AE5: GSIS | AF5: AMOUNT PAID IN CASH (CR.A-1) | AG5: N U M B E R
G6: MONTLY RATE OF PAY | N6: CONSOL | O6: POLICY LOAN | R6: PAG-IBIG CONTRIBUTION | T6: LIFE/RETIREMENT | AH6: SIGNATURE OF PAYEE | AI6: REMARKS
R7: PERSONAL SHARE | S7: GOV'T. SHARE | T7: INSURANCE PREMIUM | Z7: EDUC
P8: GSIS contribution | T8: PS | U8: GS | V8: Philhleath Cont | X8: UOLI | AB8: CAL | AC8: MPL | AE8: STATE. INSURANCE
P9: PS | Q9: GS | V9: PS | W9: GS | Y9: Optional
A10: 1 | B10: 2 | C10: 3 | D10: 4 | E10: 5 | G10: 6 | H10: 7 | I10: 8 | J10: 9 | K10: 10 | L10: 9 | M10: 10 | N10: 11 | O10: 12 | R10: 13 | S10: 14 | T10: 15 | U10: 17 | X10: 18 | Y10: 19 | Z10: 20 | AA10: 21 | AB10: 22 | AC10: 22 | AD10: 26 | AF10: 24 | AG10: 25 | AH10: 26 | AI10: 27
B12: 8852
A13: 1 | B13: JAY - AR MANALO | C13: Admin Aide I | D13: Mar. 16-31, 2017 | F13: 9 | G13: =ROUND(7582/22,2) -> 344.64 | H13: =G13*F13 -> 3101.76 | R13: =ROUND(G13*22*0.02,2) -> 151.64 | S13: =R13 -> 151.64 | AF13: =H13-(SUM(I13:R13)+T13+SUM(V13:AD13)) -> 2950.12 | AG13: 1
A14: 2 | B14: REGIE MANALO | C14: Admin Aide I | D14: -do- | F14: 11 | G14: =ROUND(7582/22,2) -> 344.64 | H14: =G14*F14 -> 3791.04 | I14: 209.55 | L14: 0 | N14: 0 | O14: 0 | R14: =ROUND(G14*22*0.02,2) -> 151.64 | S14: =R14 -> 151.64 | T14: 0 | U14: 0 | X14: 0 | Y14: 0 | Z14: 0 | AB14: 0 | AC14: 0 | AF14: =H14-(SUM(I14:R14)+T14+SUM(V14:AD14)) -> 3429.85 | AG14: 2
H21: =SUM(H13:H15) -> 6892.8 | I21: =SUM(I13:I15) -> 209.55 | J21: =SUM(J13:J15) -> 0 | K21: =SUM(K13:K15) -> 0 | L21: =SUM(L13:L15) -> 0 | M21: =SUM(M13:M15) -> 0 | N21: =SUM(N13:N15) -> 0 | O21: =SUM(O13:O15) -> 0 | ... AF21: =SUM(AF13:AF15) -> 6379.97
A23: (1) I HEREBY CERTIFY on my official oath that the above PAYROLL is correct, and that services above stated have been duly rendered. Payment for such services is also hereby approved from the appropriation indicated. | R23: APPROVED:
AC24: (5) I HEREBY CERTIFY on my official oath that I have paid in cash to each official and employee whose name appears on the above roll the amount set opposite his name, under column 22, he having signed or marked his name under column 24 above, in my presence and at the time that payment was made to him, in acknowledgement of receipt of the money paid him.
R25: GIRLIE JAVIER EJERCITO
R26: Municipal Mayor
D27: ARCH. MANSLEY G. KIMHOKO | R27: Chief of Office
D28: Municipal Tourism Officer
A30: (2) APPROVED for payment subject to preaudit:
AC31: (6) I HEREBY CERTIFY on my official oath that each employee whose name appears on the above roll has been paid in cash or in check, and in no other mode, the amount shown under column 22 above, opposite his name. The total of the payments made by means this payroll amount to
E32: Treasurer
A33: (3) Preaudited and approved for payment in the month of
C34: (P ) | E34: pesos only. | AI34: Treasurer

Sheet CasualMHO16-31
A1: Municipal P A Y R O L L
A2: WE HEREBY ACKNOWLEDGE TO HAVE RECEIVED FROM MINERVA L. BOONGALING, TREASURER OF PAGSANJAN, LAGUNA THE SUMS HEREIN SPECIFIED OPPOSITES OUR RESPECTIVE NAMES, THE SAME BEING FULL COMPENSATION FOR OUR SERVICES RENDERED DURING THE PERIOD STATED BELOW, TO THE CORRECTNESS OF WHICH WE HEREBY SEVERALLY
A4: NO. | B4: NAME | C4: DESIGNATION | D4: PERIOD OF SERVICE (INCLUSIVE DATES) | H4: AMOUNT ACCRUED FOR THE PERIOD | I4: D E D U C T I O N S
D5: FROM | E5: TO | I5: Withholding Tax | J5: SOS | K5: ESL | L5: EL | Y5: PAG-IBIG | AD5: GSIS | AE5: AMOUNT PAID IN CASH (CR.A-1) | AF5: N U M B E R
G6: MONTLY RATE OF PAY | N6: CONSOL | O6: POLICY LOAN | P6: PAG-IBIG CONTRIBUTION | R6: LIFE/RETIREMENT | T6: Philhealth | AG6: SIGNATURE OF PAYEE | AH6: REMARKS
P7: PERSONAL SHARE | Q7: GOV'T. SHARE | R7: INSURANCE PREMIUM | X7: EDUC | AC7: STATE. INSURANCE
F8: No. of | R8: PERSONAL SHARE | S8: GOVERNMENT SHARE | T8: PERSONAL SHARE | U8: GOVERNMENT SHARE | Z8: CAL | AA8: MPL | AD8: STATE. INSURANCE
F9: days | V9: UOLI | W9: Optional
A10: 1 | B10: 2 | C10: 3 | D10: 4 | E10: 5 | G10: 6 | H10: 7 | I10: 8 | J10: 9 | K10: 10 | L10: 9 | M10: 10 | N10: 11 | O10: 12 | P10: 13 | Q10: 14 | R10: 15 | S10: 17 | U10: 17 | V10: 18 | W10: 19 | X10: 20 | Y10: 21 | Z10: 22 | AA10: 22 | AB10: 26 | AC10: 23 | AE10: 24 | AF10: 25 | AG10: 26 | AH10: 27
A11: 1 | B11: 4411 | AF11: 1
A12: 2 | B12: LYKA NADERA | C12: Admin Aide I | D12: Mar. 16-28, 2017 | F12: 14 | G12: 430.82 | H12: =G12*F12 -> 6031.48 | L12: 0 | O12: 0 | P12: =ROUND(G12*22*0.02,2) -> 189.56 | Q12: =P12 -> 189.56 | V12: 0 | X12: 0 | AE12: =H12-(SUM(I12:P12)+R12+SUM(U12:AB12)) -> 5841.92 | AF12: 2
A13: 3 | B13: HERMINIO WATSON | C13: Admin Aide I | D13: -do- | F13: 14 | G13: 430.82 | H13: =G13*F13 -> 6031.48 | I13: 246.16 | L13: 0 | O13: 0 | P13: =ROUND(G13*22*0.02,2) -> 189.56 | Q13: =P13 -> 189.56 | V13: 0 | X13: 0 | AE13: =H13-(SUM(I13:P13)+R13+SUM(U13:AB13)) -> 5595.76 | AF13: 3
A14: 4 | AF14: 4
A15: 5 | AF15: 5
A16: 6 | AF16: 6
A17: 7 | AF17: 7
A18: 8 | AF18: 8
A19: 9 | AF19: 9
A20: 10 | AF20: 10
A21: 11 | AF21: 11
A22: 12 | AF22: 12
A23: 13 | AF23: 13
A24: 14 | AF24: 14
A25: 15 | H25: =SUM(H12:H24) -> 12062.96 | I25: =SUM(I12:I24) -> 246.16 | J25: =SUM(J12:J24) -> 0 | K25: =SUM(K12:K24) -> 0 | P25: =SUM(P12:P24) -> 379.12 | Q25: =SUM(Q12:Q24) -> 379.12 | R25: =SUM(R12:R24) -> 0 | S25: =SUM(S12:S24) -> 0 | T25: =SUM(T12:T24) -> 0 | U25: =SUM(U12:U24) -> 0 | V25: =SUM(V12:V24) -> 0 | W25: =SUM(W12:W24) -> 0 | ... Y25: =SUM(Y12:Y24) -> 0 | AE25: =SUM(AE12:AE24) -> 11437.68 | AF25: 15
I27: APPROVED: | AC27: (5) I HEREBY CERTIFY on my official oath that I have paid in cash to each official and employee whose name appears on the above roll the amount set opposite his name, under column 22, he having signed or marked his name under column 24 above, in my presence and at the time that payment was made to him, in acknowledgement of receipt of the money paid him.
A28: (1) I HEREBY CERTIFY on my official oath that the above PAYROLL is correct, and that services above stated have been duly rendered. Payment for such services is also hereby approved from the appropriation indicated.
J30: GIRLIE JAVIER EJERCITO
J31: Municipal Mayor
D32: DR. LYRA LERON TORRES | J32: Chief of Office
D33: Municipal Health Officer
A35: (2) APPROVED for payment subject to preaudit:
AC36: (6) I HEREBY CERTIFY on my official oath that each employee whose name appears on the above roll has been paid in cash or in check, and in no other mode, the amount shown under column 22 above, opposite his name. The total of the payments made by means this payroll amount to
E37: Treasurer
A38: (3) Preaudited and approved for payment in the month of
C39: (P ) | E39: pesos only. | AH39: Treasurer

Sheet Casual 1-15 (SB)
A1: Municipal P A Y R O L L
A2: WE HEREBY ACKNOWLEDGE TO HAVE RECEIVED FROM MINERVA L. BOONGALING, TREASURER OF PAGSANJAN, LAGUNA THE SUMS HEREIN SPECIFIED OPPOSITES OUR RESPECTIVE NAMES, THE SAME BEING FULL COMPENSATION FOR OUR SERVICES RENDERED DURING THE PERIOD STATED BELOW, TO THE CORRECTNESS OF WHICH WE HEREBY SEVERALLY
A4: NO. | B4: NAME | C4: DESIGNATION | D4: PERIOD OF SERVICE (INCLUSIVE DATES) | H4: AMOUNT ACCRUED FOR THE PERIOD | I4: D E D U C T I O N S
D5: FROM | E5: TO | I5: HOUSING LOAN | J5: SOS | K5: ESL | L5: EL | N5: GOVERNMENT SERVICE INSURANCE SYSTEM | Z5: Pag Ibig | AC5: AMOUNT PAID IN CASH (CR.A-1) | AD5: N U M B E R
G6: MONTLY RATE OF PAY | N6: CONSOL | O6: POLICY LOAN | P6: PHILHEALTH | R6: LIFE/RETIREMENT | X6: GLOBE | Y6: RBP | AE6: SIGNATURE OF PAYEE | AF6: REMARKS
F7: No. of days | P7: PERSONAL SHARE | Q7: GOV'T. SHARE | R7: INSURANCE PREMIUM | V7: CAL | W7: EDU. CHILD | AB7: STATE. INSURANCE
R8: PERSONAL SHARE | S8: GOVERNMENT SHARE | T8: OPTIONAL | U8: Educ
Z9: MPL | AA9: CALAMITY
A10: 1 | B10: 2 | C10: 3 | D10: 4 | E10: 5 | G10: 6 | H10: 7 | I10: 8 | J10: 9 | K10: 10 | L10: 11 | M10: 12 | N10: 13 | O10: 14 | P10: 15 | Q10: 16 | R10: 17 | S10: 18 | T10: 19 | U10: 20 | V10: 21 | W10: 22 | X10: 23 | Y10: 24 | Z10: 25 | AA10: 26 | AB10: 27 | AC10: 28 | AD10: 29 | AE10: 30 | AF10: 31
B12: 1022
A13: 1 | B13: MARVIN PINILI | C13: Admin Aide I | D13: Mar. 1-15, 2017 | F13: 11 | G13: =ROUND(7582/22,2) -> 344.64 | H13: =F13*G13 -> 3791.04 | I13: 0 | L13: 0 | N13: 0 | O13: 0 | P13: 100 | Q13: =P13 -> 100 | R13: 682.38 | S13: 909.84 | AB13: 75.82 | AC13: =H13-(SUM(I13:P13)+R13+SUM(T13:AA13)) -> 3008.66 | AD13: 1
B14: 1021
A15: 2 | B15: NOWEL LERON | C15: Admin Aide I | D15: -do- | F15: 11 | G15: =ROUND(7582/22,2) -> 344.64 | H15: =F15*G15 -> 3791.04 | I15: 0 | L15: 0 | N15: 0 | O15: 0 | P15: 100 | Q15: =P15 -> 100 | R15: 682.38 | S15: 909.84 | T15: 0 | U15: 0 | V15: 0 | Z15: 0 | AA15: 0 | AB15: 75.82 | AC15: =H15-(SUM(I15:P15)+R15+SUM(T15:AA15)) -> 3008.66 | AD15: 2
H24: =SUM(H13:H23) -> 7582.08 | P24: =SUM(P13:P23) -> 200 | Q24: =SUM(Q13:Q23) -> 200 | R24: =SUM(R13:R23) -> 1364.76 | S24: =SUM(S13:S23) -> 1819.68 | AC24: =SUM(AC13:AC23) -> 6017.32
AB27: (5) I HEREBY CERTIFY on my official oath that I have paid in cash to each official and employee whose name appears on the above roll the amount set opposite his name, under column 28, he having signed or marked his name under column 30 above, in my presence and at the time that payment was made to him, in acknowledgement of receipt of the money paid him.
A28: (1) I HEREBY CERTIFY on my official oath that the above PAYROLL is correct, and that services above stated have been duly rendered. Payment for such services is also hereby approved from the appropriation indicated. | I28: (4) APPROVED
J30: DR. PETER CASIUS M. TRINIDAD
J31: Municipal Vice Mayor
D32: DR. PETER CASIUS M. TRINIDAD | J32: Chief of Office
D33: Municipal Vice Mayor
A35: (2) APPROVED for payment subject to preaudit: | AB35: (6) I HEREBY CERTIFY on my official oath that each employee whose name appears on the above roll has been paid in cash or in check, and in no other mode, the amount shown under column 21 above, opposite his name. The total of the payments made by means this payroll amount to
E37: Treasurer
A38: (3) Preaudited and approved for payment in the month of
C39: (P ) | E39: pesos only. | AF39: Treasurer

Sheet CasualSb16-31
A1: Municipal P A Y R O L L
A2: WE HEREBY ACKNOWLEDGE TO HAVE RECEIVED FROM MINERVA L. BOONGALING, TREASURER OF PAGSANJAN, LAGUNA THE SUMS HEREIN SPECIFIED OPPOSITES OUR RESPECTIVE NAMES, THE SAME BEING FULL COMPENSATION FOR OUR SERVICES RENDERED DURING THE PERIOD STATED BELOW, TO THE CORRECTNESS OF WHICH WE HEREBY SEVERALLY
A4: NO. | B4: NAME | C4: DESIGNATION | D4: PERIOD OF SERVICE (INCLUSIVE DATES) | I4: AMOUNT ACCRUED FOR THE PERIOD | J4: D E D U C T I O N S
D5: FROM | E5: TO | J5: Withholding Tax | K5: SOS | L5: ESL | M5: EL | Z5: PAG-IBIG | AE5: GSIS | AF5: AMOUNT PAID IN CASH (CR.A-1) | AG5: N U M B E R
H6: MONTLY RATE OF PAY | O6: CONSOL | P6: POLICY LOAN | Q6: PAG-IBIG CONTRIBUTION | S6: LIFE/RETIREMENT | U6: Philhealth | AH6: SIGNATURE OF PAYEE | AI6: REMARKS
F7: No. of Days | G7: Adjustment | Q7: PERSONAL SHARE | R7: GOV'T. SHARE | S7: INSURANCE PREMIUM | Y7: EDUC | AD7: STATE. INSURANCE
S8: PERSONAL SHARE | T8: GOVERNMENT SHARE | U8: PERSONAL SHARE | V8: GOVERNMENT SHARE | W8: UOLI | AA8: CAL | AB8: MPL | AE8: STATE. INSURANCE
X9: Optional
A10: 1 | B10: 2 | C10: 3 | D10: 4 | E10: 5 | H10: 6 | I10: 7 | J10: 8 | K10: 9 | L10: 10 | M10: 9 | N10: 10 | O10: 11 | P10: 12 | Q10: 13 | R10: 14 | S10: 15 | T10: 17 | V10: 17 | W10: 18 | X10: 19 | Y10: 20 | Z10: 21 | AA10: 22 | AB10: 22 | AC10: 26 | AD10: 23 | AF10: 24 | AG10: 25 | AH10: 26 | AI10: 27
B11: 1016-1021-1022
A12: 1 | B12: JOWEL PALACOL | C12: Admin Aide I | D12: Mar. 16-31, 2017 | F12: 11 | G12: 1 | H12: =ROUND(7582/22,2) -> 344.64 | I12: =H12*12 -> 4135.68 | M12: 0 | P12: 0 | Q12: =ROUND(H12*22*0.02,2) -> 151.64 | R12: =Q12 -> 151.64 | W12: 0 | Y12: 0 | AF12: =I12-(SUM(J12:Q12)+S12+SUM(V12:AC12)) -> 3984.04
A13: 2 | B13: MARVIN P. PINILI | C13: Admin Aide I | D13: -do- | F13: 12 | G13: 1 | H13: =ROUND(7582/22,2) -> 344.64 | I13: =H13*13 -> 4480.32 | J13: 209.55 | M13: 0 | O13: 0 | P13: 0 | Q13: =ROUND(H13*22*0.02,2) -> 151.64 | R13: =Q13 -> 151.64 | S13: 0 | T13: 0 | W13: 0 | X13: 0 | Y13: 0 | AA13: 0 | AB13: 0 | AF13: =I13-(SUM(J13:Q13)+S13+SUM(V13:AC13)) -> 4119.13
